<?xml version="1.0"?>

<robot xmlns:xacro="http://www.ros.org/wiki/xacro">

	<!-- Import all Gazebo-customization elements, including Gazebo colors -->
	<xacro:include filename="$(find bhand_description)/urdf/bh282.gazebo" />

	<!-- Constants for robot dimensions -->
	<xacro:property name="PI" value="3.1415926535897931"/>
	<xacro:property name="PI_2" value="1.570796327"/>
	<xacro:property name="joint_damping" value="100.0" />
	<xacro:property name="joint_friction" value="1.0" />
	<xacro:property name="joint_effort_limit" value="30.0" />
	<xacro:property name="joint_velocity_limit" value="2.0" />
	<xacro:property name="mechanical_reduction" value="1.0" />


	<xacro:macro name="bhand_macro" params="parent name *origin">

		<joint name="${name}_base_joint" type="fixed">
			<insert_block name="origin"/>
			<parent link="${parent}"/>
			<child link="${name}_base_link"/>
		</joint>

		<!-- HAND BASE_LINK (RED) -->
		<link name="${name}_base_link">
			<inertial>
			  <mass value="1.0" />
			  <origin xyz="0 0 0" />
			  <inertia  ixx="1.0" ixy="0.0"  ixz="0.0"  iyy="1.0"  iyz="0.0"  izz="1.0" />
			</inertial>
			<visual>
			   <origin xyz="0 0 0" rpy="0 0 0" />
			   <geometry>
				  <mesh filename="package://bhand_description/meshes/stl/dmt_palm.stl"/>
			   </geometry>
			   <material name="Grey">
				  <color rgba="0.75 0.75 0.75 1.0"/>
			   </material>
			</visual>
			<collision>
			   <origin xyz="0 0 0" rpy="0 0 0 " />
			   <geometry>
				  <mesh filename="package://bhand_description/meshes/stl/dmt_palm.stl"/>
			   </geometry>
			   <contact_coefficients kd="1.0" kp="1000.0" mu="0"/>
			</collision>
		</link>


		<!-- finger 3 -->
		<!-- finger 31 link -->
		<link name="${name}_finger_3_link">
		 <inertial>
		   <mass value="0.1"/>
		   <origin xyz="-0.046 0 0" rpy="0 0 0"/>
		   <inertia ixx="0.01" ixy="0" ixz="0" iyy="0.01" iyz="0" izz="0.01" />
		 </inertial>
		 <visual>
		   <origin xyz="-0.04 0 0" rpy="0 0 0" />
		   <geometry>
			  <mesh filename="package://bhand_description/meshes/stl/dmt_finger.stl" />
		   </geometry>
		   <material name="Black"/>
		 </visual>
		 <collision>
		   <origin xyz="-0.04 0 0" rpy="0 0 0" />
		   <geometry>
			  <mesh filename="package://bhand_description/meshes/stl/dmt_finger.stl"/>
		   </geometry>
		   <contact_coefficients kd="1.0" kp="1000.0" mu="0"/>
		  </collision>
		</link>

		<!-- joint between BH_palm_link and BH_finger_3_link -->
		<!-- finger3 is the center finger and is fixed -->
		<joint name="${name}_j31_joint" type="fixed">
			<parent link="${name}_base_link"/>
			<child link="${name}_finger_3_link"/>
			<origin xyz="0 0 0.0252" rpy="0 0 -${PI_2}"/>
		</joint>

		<transmission name="${name}_j31_transmission">
			<type>transmission_interface/SimpleTransmission</type>
			<joint name="${name}_j31_joint"/>
			<actuator name="${name}_j31">
			  <hardwareInterface>PositionJointInterface</hardwareInterface>
			  <mechanicalReduction>1</mechanicalReduction>
			  <motorTorqueConstant>1</motorTorqueConstant>
			</actuator>
		</transmission>




		<!-- finger 1 -->
		<!-- finger 11 link -->
		<link name="${name}_finger_1_link">
			<inertial>
			  <mass value="0.1"/>
			  <origin xyz="-0.046 0 0" rpy="0 0 0"/>
			  <inertia ixx="0.01" ixy="0" ixz="0" iyy="0.01" iyz="0" izz="0.01" />
			</inertial>
			<visual>
			  <origin xyz="0 0 0" rpy="0 0 0" />
			  <geometry>
				 <mesh filename="package://bhand_description/meshes/stl/dmt_finger.stl" />
			  </geometry>
			  <material name="Green" />
			</visual>
			<collision>
			  <origin xyz="0 0 0" rpy="0 0 0" />
			  <geometry>
				<mesh filename="package://bhand_description/meshes/stl/dmt_finger.stl" />
			  </geometry>
			</collision>
		</link>

		<!-- joint between BH_palm_link and BH_finger_1_link -->
		<joint name="${name}_j11_joint" type="revolute">
			<parent link="${name}_base_link"/>
			<child link="${name}_finger_1_link"/>
			<origin xyz="-0.025 0 0.0252" rpy="0 0 1.5708" />
			<axis xyz="0 0 -1"/>
			<limit effort="${joint_effort_limit}" lower="0" upper="3.1416" velocity="${joint_velocity_limit}"/>
			<dynamics damping="${joint_damping}" friction="${joint_friction}"/>
		</joint>

		<transmission name="${name}_j11_transmission">
			<type>transmission_interface/SimpleTransmission</type>
			<joint name="${name}_j11_joint"/>
			<actuator name="${name}_j11">
			  <hardwareInterface>PositionJointInterface</hardwareInterface>
			  <mechanicalReduction>1</mechanicalReduction>
			  <motorTorqueConstant>1</motorTorqueConstant>
			</actuator>
		</transmission>


		<!-- finger 2 -->
		<!-- finger 21 link -->
		<link name="${name}_finger_2_link">
			<inertial>
			  <mass value="0.1"/>
			  <origin xyz="-0.046 0 0" rpy="0 0 0"/>
			  <inertia ixx="0.01" ixy="0" ixz="0" iyy="0.01" iyz="0" izz="0.01" />
			</inertial>
			<visual>
			  <origin xyz="0 0 0" rpy="0 0 0" />
			  <geometry>
				 <mesh filename="package://bhand_description/meshes/stl/dmt_finger.stl" />
			  </geometry>
			  <material name="Green" />
			</visual>
			<collision>
			  <origin xyz="0 0 0" rpy="0 0 0" />
			  <geometry>
				<mesh filename="package://bhand_description/meshes/stl/dmt_finger.stl" />
			  </geometry>
			</collision>
		</link>

		<!-- joint between BH_palm_link and BH_finger_2_link -->
		<joint name="${name}_j21_joint" type="revolute">
			<parent link="${name}_base_link"/>
			<child link="${name}_finger_2_link"/>
			<origin xyz="0.025 0 0.0252" rpy="0 0 1.5708" />
			<axis xyz="0 0 1"/>
			<limit effort="${joint_effort_limit}" lower="0" upper="3.1416" velocity="${joint_velocity_limit}"/>
			<dynamics damping="${joint_damping}" friction="${joint_friction}"/>
		</joint>

		<transmission name="${name}_j21_transmission">
			<type>transmission_interface/SimpleTransmission</type>
			<joint name="${name}_j21_joint"/>
			<actuator name="${name}_j21">
			  <hardwareInterface>PositionJointInterface</hardwareInterface>
			  <mechanicalReduction>1</mechanicalReduction>
			  <motorTorqueConstant>1</motorTorqueConstant>
			</actuator>
		</transmission>

		<xacro:bh_gazebo name="${name}"/>

	</xacro:macro>

</robot>
